2025-06-11 22:41:18,705 ERROR: Exception on /register [POST] [in C:\Users\Hi\Desktop\project cá nhân\Microblog\venv\Lib\site-packages\flask\app.py:875]
Traceback (most recent call last):
  File "C:\Users\Hi\Desktop\project cá nhân\Microblog\venv\Lib\site-packages\wtforms\validators.py", line 401, in __call__
    import email_validator
ModuleNotFoundError: No module named 'email_validator'

The above exception was the direct cause of the following exception:

Traceback (most recent call last):
  File "C:\Users\Hi\Desktop\project cá nhân\Microblog\venv\Lib\site-packages\flask\app.py", line 1511, in wsgi_app
    response = self.full_dispatch_request()
  File "C:\Users\Hi\Desktop\project cá nhân\Microblog\venv\Lib\site-packages\flask\app.py", line 919, in full_dispatch_request
    rv = self.handle_user_exception(e)
  File "C:\Users\Hi\Desktop\project cá nhân\Microblog\venv\Lib\site-packages\flask\app.py", line 917, in full_dispatch_request
    rv = self.dispatch_request()
  File "C:\Users\Hi\Desktop\project cá nhân\Microblog\venv\Lib\site-packages\flask\app.py", line 902, in dispatch_request
    return self.ensure_sync(self.view_functions[rule.endpoint])(**view_args)  # type: ignore[no-any-return]
           ~~~~~~~~~~~~~~~~~~~~~~~~~~~~~~~~~~~~~~~~~~~~~~~~~~~~^^^^^^^^^^^^^
  File "C:\Users\Hi\Desktop\project cá nhân\Microblog\app\routes.py", line 68, in register
    if form.validate_on_submit():
       ~~~~~~~~~~~~~~~~~~~~~~~^^
  File "C:\Users\Hi\Desktop\project cá nhân\Microblog\venv\Lib\site-packages\flask_wtf\form.py", line 86, in validate_on_submit
    return self.is_submitted() and self.validate(extra_validators=extra_validators)
                                   ~~~~~~~~~~~~~^^^^^^^^^^^^^^^^^^^^^^^^^^^^^^^^^^^
  File "C:\Users\Hi\Desktop\project cá nhân\Microblog\venv\Lib\site-packages\wtforms\form.py", line 330, in validate
    return super().validate(extra)
           ~~~~~~~~~~~~~~~~^^^^^^^
  File "C:\Users\Hi\Desktop\project cá nhân\Microblog\venv\Lib\site-packages\wtforms\form.py", line 147, in validate
    if not field.validate(self, extra):
           ~~~~~~~~~~~~~~^^^^^^^^^^^^^
  File "C:\Users\Hi\Desktop\project cá nhân\Microblog\venv\Lib\site-packages\wtforms\fields\core.py", line 234, in validate
    stop_validation = self._run_validation_chain(form, chain)
  File "C:\Users\Hi\Desktop\project cá nhân\Microblog\venv\Lib\site-packages\wtforms\fields\core.py", line 254, in _run_validation_chain
    validator(form, self)
    ~~~~~~~~~^^^^^^^^^^^^
  File "C:\Users\Hi\Desktop\project cá nhân\Microblog\venv\Lib\site-packages\wtforms\validators.py", line 403, in __call__
    raise Exception(
        "Install 'email_validator' for email validation support."
    ) from exc
Exception: Install 'email_validator' for email validation support.
2025-06-11 22:42:46,163 INFO: Microblog startup [in C:\Users\Hi\Desktop\project cá nhân\Microblog\app\__init__.py:43]
2025-06-19 17:42:13,990 INFO: Microblog startup [in C:\Users\Hi\Desktop\project cá nhân\Microblog\app\__init__.py:44]
2025-07-05 09:14:03,109 INFO: Microblog startup [in C:\Users\Hi\Desktop\project cá nhân\Microblog\app\__init__.py:49]
2025-07-05 09:19:53,103 INFO: Microblog startup [in C:\Users\Hi\Desktop\project cá nhân\Microblog\app\__init__.py:49]
2025-07-05 09:20:28,778 INFO: Microblog startup [in C:\Users\Hi\Desktop\project cá nhân\Microblog\app\__init__.py:49]
2025-07-05 09:21:05,630 INFO: Microblog startup [in C:\Users\Hi\Desktop\project cá nhân\Microblog\app\__init__.py:49]
2025-07-05 09:27:03,732 INFO: Microblog startup [in C:\Users\Hi\Desktop\project cá nhân\Microblog\app\__init__.py:49]
